Workbook

Sheet Resumen
A1: Tablero de mermas · Agosto 2026
A2: Periodo: Agosto 2026 · Generado: 22/09/2026 17:01 · Límite SAT: merma ≤ 0.5% de la venta
A4: Merma total grupo (L) | D4: Merma total grupo % | G4: Merma total grupo ($)
A5: ='Mermas mensual'!I23 -> 26324.11 | D5: ='Mermas mensual'!J23 -> 0.0048954769 | G5: ='Mermas mensual'!M23 -> 509745.69
A7: Combinaciones FUERA | D7: Pipas NO registradas | G7: Compras sin pipa
A8: =COUNTIF('Mermas mensual'!K5:K22,"FUERA") -> 12 | D8: =COUNTIF('Detalle pipas'!L5:L281,"NO REGISTRADA*") -> 1 | G8: =COUNTA('Compras sin pipa'!D5:D5)+COUNTIF('Registros manuales'!$G$5:$G$104,"SIN PIPA*") -> 0
A10: Merma % mensual por estación y producto
A11: Estación | B11: Regular | C11: Premium | D11: Diesel | E11: Total estación | F11: Merma (L) | G11: Merma ($) | H11: Compras vs pipas | I11: Pipas sin registrar
A12: ATB | B12: =IF(COUNTIFS('Mermas mensual'!$A$5:$A$22,$A12,'Mermas mensual'!$B$5:$B$22,"Regular")=0,"s/d",IF(SUMIFS('Mermas mensual'!$E$5:$E$22,'Mermas mensual'!$A$5:$A$22,$A12,'Mermas mensual'!$B$5:$B$22,"Regular")=0,0,SUMIFS('Mermas mensual'!$I$5:$I$22,'Mermas mensual'!$A$5:$A$22,$A12,'Mermas mensual'!$B$5:$B$22,"Regular")/SUMIFS('Mermas mensual'!$E$5:$E$22,'Mermas mensual'!$A$5:$A$22,$A12,'Mermas mensual'!$B$5:$B$22,"Regular"))) -> s/d | C12: =IF(COUNTIFS('Mermas mensual'!$A$5:$A$22,$A12,'Mermas mensual'!$B$5:$B$22,"Premium")=0,"s/d",IF(SUMIFS('Mermas mensual'!$E$5:$E$22,'Mermas mensual'!$A$5:$A$22,$A12,'Mermas mensual'!$B$5:$B$22,"Premium")=0,0,SUMIFS('Mermas mensual'!$I$5:$I$22,'Mermas mensual'!$A$5:$A$22,$A12,'Mermas mensual'!$B$5:$B$22,"Premium")/SUMIFS('Mermas mensual'!$E$5:$E$22,'Mermas mensual'!$A$5:$A$22,$A12,'Mermas mensual'!$B$5:$B$22,"Premium"))) -> s/d | D12: =IF(COUNTIFS('Mermas mensual'!$A$5:$A$22,$A12,'Mermas mensual'!$B$5:$B$22,"Diesel")=0,"s/d",IF(SUMIFS('Mermas mensual'!$E$5:$E$22,'Mermas mensual'!$A$5:$A$22,$A12,'Mermas mensual'!$B$5:$B$22,"Diesel")=0,0,SUMIFS('Mermas mensual'!$I$5:$I$22,'Mermas mensual'!$A$5:$A$22,$A12,'Mermas mensual'!$B$5:$B$22,"Diesel")/SUMIFS('Mermas mensual'!$E$5:$E$22,'Mermas mensual'!$A$5:$A$22,$A12,'Mermas mensual'!$B$5:$B$22,"Diesel"))) -> s/d | E12: =IF(COUNTIF('Mermas mensual'!$A$5:$A$22,$A12)=0,"s/d",IF(SUMIFS('Mermas mensual'!$E$5:$E$22,'Mermas mensual'!$A$5:$A$22,$A12)=0,0,SUMIFS('Mermas mensual'!$I$5:$I$22,'Mermas mensual'!$A$5:$A$22,$A12)/SUMIFS('Mermas mensual'!$E$5:$E$22,'Mermas mensual'!$A$5:$A$22,$A12))) -> s/d | F12: =IF(COUNTIF('Mermas mensual'!$A$5:$A$22,$A12)=0,"s/d",SUMIFS('Mermas mensual'!$I$5:$I$22,'Mermas mensual'!$A$5:$A$22,$A12)) -> s/d | G12: =IF(COUNTIF('Mermas mensual'!$A$5:$A$22,$A12)=0,"s/d",SUMIFS('Mermas mensual'!$M$5:$M$22,'Mermas mensual'!$A$5:$A$22,$A12)) -> s/d | H12: =IF(COUNTIFS('Conciliación pipas'!$A$5:$A$40,$A12,'Conciliación pipas'!$G$5:$G$40,"NO CUADRA")>0,"NO CUADRA",IF(COUNTIFS('Conciliación pipas'!$A$5:$A$40,$A12,'Conciliación pipas'!$G$5:$G$40,"CUADRA")>0,IF(COUNTIFS('Conciliación pipas'!$A$5:$A$40,$A12,'Conciliación pipas'!$G$5:$G$40,"SIN REPORTE")>0,"PARCIAL","CUADRA"),IF(COUNTIF('Conciliación pipas'!$A$5:$A$40,$A12)=0,"s/d","SIN REPORTE"))) -> SIN REPORTE | I12: =SUMIFS('Conciliación pipas'!$H$5:$H$40,'Conciliación pipas'!$A$5:$A$40,$A12) -> 0
A13: ATP | B13: =IF(COUNTIFS('Mermas mensual'!$A$5:$A$22,$A13,'Mermas mensual'!$B$5:$B$22,"Regular")=0,"s/d",IF(SUMIFS('Mermas mensual'!$E$5:$E$22,'Mermas mensual'!$A$5:$A$22,$A13,'Mermas mensual'!$B$5:$B$22,"Regular")=0,0,SUMIFS('Mermas mensual'!$I$5:$I$22,'Mermas mensual'!$A$5:$A$22,$A13,'Mermas mensual'!$B$5:$B$22,"Regular")/SUMIFS('Mermas mensual'!$E$5:$E$22,'Mermas mensual'!$A$5:$A$22,$A13,'Mermas mensual'!$B$5:$B$22,"Regular"))) -> s/d | C13: =IF(COUNTIFS('Mermas mensual'!$A$5:$A$22,$A13,'Mermas mensual'!$B$5:$B$22,"Premium")=0,"s/d",IF(SUMIFS('Mermas mensual'!$E$5:$E$22,'Mermas mensual'!$A$5:$A$22,$A13,'Mermas mensual'!$B$5:$B$22,"Premium")=0,0,SUMIFS('Mermas mensual'!$I$5:$I$22,'Mermas mensual'!$A$5:$A$22,$A13,'Mermas mensual'!$B$5:$B$22,"Premium")/SUMIFS('Mermas mensual'!$E$5:$E$22,'Mermas mensual'!$A$5:$A$22,$A13,'Mermas mensual'!$B$5:$B$22,"Premium"))) -> s/d | D13: =IF(COUNTIFS('Mermas mensual'!$A$5:$A$22,$A13,'Mermas mensual'!$B$5:$B$22,"Diesel")=0,"s/d",IF(SUMIFS('Mermas mensual'!$E$5:$E$22,'Mermas mensual'!$A$5:$A$22,$A13,'Mermas mensual'!$B$5:$B$22,"Diesel")=0,0,SUMIFS('Mermas mensual'!$I$5:$I$22,'Mermas mensual'!$A$5:$A$22,$A13,'Mermas mensual'!$B$5:$B$22,"Diesel")/SUMIFS('Mermas mensual'!$E$5:$E$22,'Mermas mensual'!$A$5:$A$22,$A13,'Mermas mensual'!$B$5:$B$22,"Diesel"))) -> s/d | E13: =IF(COUNTIF('Mermas mensual'!$A$5:$A$22,$A13)=0,"s/d",IF(SUMIFS('Mermas mensual'!$E$5:$E$22,'Mermas mensual'!$A$5:$A$22,$A13)=0,0,SUMIFS('Mermas mensual'!$I$5:$I$22,'Mermas mensual'!$A$5:$A$22,$A13)/SUMIFS('Mermas mensual'!$E$5:$E$22,'Mermas mensual'!$A$5:$A$22,$A13))) -> s/d | F13: =IF(COUNTIF('Mermas mensual'!$A$5:$A$22,$A13)=0,"s/d",SUMIFS('Mermas mensual'!$I$5:$I$22,'Mermas mensual'!$A$5:$A$22,$A13)) -> s/d | G13: =IF(COUNTIF('Mermas mensual'!$A$5:$A$22,$A13)=0,"s/d",SUMIFS('Mermas mensual'!$M$5:$M$22,'Mermas mensual'!$A$5:$A$22,$A13)) -> s/d | H13: =IF(COUNTIFS('Conciliación pipas'!$A$5:$A$40,$A13,'Conciliación pipas'!$G$5:$G$40,"NO CUADRA")>0,"NO CUADRA",IF(COUNTIFS('Conciliación pipas'!$A$5:$A$40,$A13,'Conciliación pipas'!$G$5:$G$40,"CUADRA")>0,IF(COUNTIFS('Conciliación pipas'!$A$5:$A$40,$A13,'Conciliación pipas'!$G$5:$G$40,"SIN REPORTE")>0,"PARCIAL","CUADRA"),IF(COUNTIF('Conciliación pipas'!$A$5:$A$40,$A13)=0,"s/d","SIN REPORTE"))) -> SIN REPORTE | I13: =SUMIFS('Conciliación pipas'!$H$5:$H$40,'Conciliación pipas'!$A$5:$A$40,$A13) -> 0
A14: AVE FENIX | B14: =IF(COUNTIFS('Mermas mensual'!$A$5:$A$22,$A14,'Mermas mensual'!$B$5:$B$22,"Regular")=0,"s/d",IF(SUMIFS('Mermas mensual'!$E$5:$E$22,'Mermas mensual'!$A$5:$A$22,$A14,'Mermas mensual'!$B$5:$B$22,"Regular")=0,0,SUMIFS('Mermas mensual'!$I$5:$I$22,'Mermas mensual'!$A$5:$A$22,$A14,'Mermas mensual'!$B$5:$B$22,"Regular")/SUMIFS('Mermas mensual'!$E$5:$E$22,'Mermas mensual'!$A$5:$A$22,$A14,'Mermas mensual'!$B$5:$B$22,"Regular"))) -> s/d | C14: =IF(COUNTIFS('Mermas mensual'!$A$5:$A$22,$A14,'Mermas mensual'!$B$5:$B$22,"Premium")=0,"s/d",IF(SUMIFS('Mermas mensual'!$E$5:$E$22,'Mermas mensual'!$A$5:$A$22,$A14,'Mermas mensual'!$B$5:$B$22,"Premium")=0,0,SUMIFS('Mermas mensual'!$I$5:$I$22,'Mermas mensual'!$A$5:$A$22,$A14,'Mermas mensual'!$B$5:$B$22,"Premium")/SUMIFS('Mermas mensual'!$E$5:$E$22,'Mermas mensual'!$A$5:$A$22,$A14,'Mermas mensual'!$B$5:$B$22,"Premium"))) -> s/d | D14: =IF(COUNTIFS('Mermas mensual'!$A$5:$A$22,$A14,'Mermas mensual'!$B$5:$B$22,"Diesel")=0,"s/d",IF(SUMIFS('Mermas mensual'!$E$5:$E$22,'Mermas mensual'!$A$5:$A$22,$A14,'Mermas mensual'!$B$5:$B$22,"Diesel")=0,0,SUMIFS('Mermas mensual'!$I$5:$I$22,'Mermas mensual'!$A$5:$A$22,$A14,'Mermas mensual'!$B$5:$B$22,"Diesel")/SUMIFS('Mermas mensual'!$E$5:$E$22,'Mermas mensual'!$A$5:$A$22,$A14,'Mermas mensual'!$B$5:$B$22,"Diesel"))) -> s/d | E14: =IF(COUNTIF('Mermas mensual'!$A$5:$A$22,$A14)=0,"s/d",IF(SUMIFS('Mermas mensual'!$E$5:$E$22,'Mermas mensual'!$A$5:$A$22,$A14)=0,0,SUMIFS('Mermas mensual'!$I$5:$I$22,'Mermas mensual'!$A$5:$A$22,$A14)/SUMIFS('Mermas mensual'!$E$5:$E$22,'Mermas mensual'!$A$5:$A$22,$A14))) -> s/d | F14: =IF(COUNTIF('Mermas mensual'!$A$5:$A$22,$A14)=0,"s/d",SUMIFS('Mermas mensual'!$I$5:$I$22,'Mermas mensual'!$A$5:$A$22,$A14)) -> s/d | G14: =IF(COUNTIF('Mermas mensual'!$A$5:$A$22,$A14)=0,"s/d",SUMIFS('Mermas mensual'!$M$5:$M$22,'Mermas mensual'!$A$5:$A$22,$A14)) -> s/d | H14: =IF(COUNTIFS('Conciliación pipas'!$A$5:$A$40,$A14,'Conciliación pipas'!$G$5:$G$40,"NO CUADRA")>0,"NO CUADRA",IF(COUNTIFS('Conciliación pipas'!$A$5:$A$40,$A14,'Conciliación pipas'!$G$5:$G$40,"CUADRA")>0,IF(COUNTIFS('Conciliación pipas'!$A$5:$A$40,$A14,'Conciliación pipas'!$G$5:$G$40,"SIN REPORTE")>0,"PARCIAL","CUADRA"),IF(COUNTIF('Conciliación pipas'!$A$5:$A$40,$A14)=0,"s/d","SIN REPORTE"))) -> SIN REPORTE | I14: =SUMIFS('Conciliación pipas'!$H$5:$H$40,'Conciliación pipas'!$A$5:$A$40,$A14) -> 0
A15: AURORA | B15: =IF(COUNTIFS('Mermas mensual'!$A$5:$A$22,$A15,'Mermas mensual'!$B$5:$B$22,"Regular")=0,"s/d",IF(SUMIFS('Mermas mensual'!$E$5:$E$22,'Mermas mensual'!$A$5:$A$22,$A15,'Mermas mensual'!$B$5:$B$22,"Regular")=0,0,SUMIFS('Mermas mensual'!$I$5:$I$22,'Mermas mensual'!$A$5:$A$22,$A15,'Mermas mensual'!$B$5:$B$22,"Regular")/SUMIFS('Mermas mensual'!$E$5:$E$22,'Mermas mensual'!$A$5:$A$22,$A15,'Mermas mensual'!$B$5:$B$22,"Regular"))) -> 0.044792954 | C15: =IF(COUNTIFS('Mermas mensual'!$A$5:$A$22,$A15,'Mermas mensual'!$B$5:$B$22,"Premium")=0,"s/d",IF(SUMIFS('Mermas mensual'!$E$5:$E$22,'Mermas mensual'!$A$5:$A$22,$A15,'Mermas mensual'!$B$5:$B$22,"Premium")=0,0,SUMIFS('Mermas mensual'!$I$5:$I$22,'Mermas mensual'!$A$5:$A$22,$A15,'Mermas mensual'!$B$5:$B$22,"Premium")/SUMIFS('Mermas mensual'!$E$5:$E$22,'Mermas mensual'!$A$5:$A$22,$A15,'Mermas mensual'!$B$5:$B$22,"Premium"))) -> -0.0065614899 | D15: =IF(COUNTIFS('Mermas mensual'!$A$5:$A$22,$A15,'Mermas mensual'!$B$5:$B$22,"Diesel")=0,"s/d",IF(SUMIFS('Mermas mensual'!$E$5:$E$22,'Mermas mensual'!$A$5:$A$22,$A15,'Mermas mensual'!$B$5:$B$22,"Diesel")=0,0,SUMIFS('Mermas mensual'!$I$5:$I$22,'Mermas mensual'!$A$5:$A$22,$A15,'Mermas mensual'!$B$5:$B$22,"Diesel")/SUMIFS('Mermas mensual'!$E$5:$E$22,'Mermas mensual'!$A$5:$A$22,$A15,'Mermas mensual'!$B$5:$B$22,"Diesel"))) -> 0.0017236447 | E15: =IF(COUNTIF('Mermas mensual'!$A$5:$A$22,$A15)=0,"s/d",IF(SUMIFS('Mermas mensual'!$E$5:$E$22,'Mermas mensual'!$A$5:$A$22,$A15)=0,0,SUMIFS('Mermas mensual'!$I$5:$I$22,'Mermas mensual'!$A$5:$A$22,$A15)/SUMIFS('Mermas mensual'!$E$5:$E$22,'Mermas mensual'!$A$5:$A$22,$A15))) -> 0.029270285 | F15: =IF(COUNTIF('Mermas mensual'!$A$5:$A$22,$A15)=0,"s/d",SUMIFS('Mermas mensual'!$I$5:$I$22,'Mermas mensual'!$A$5:$A$22,$A15)) -> 29187.44 | G15: =IF(COUNTIF('Mermas mensual'!$A$5:$A$22,$A15)=0,"s/d",SUMIFS('Mermas mensual'!$M$5:$M$22,'Mermas mensual'!$A$5:$A$22,$A15)) -> 553962.05 | H15: =IF(COUNTIFS('Conciliación pipas'!$A$5:$A$40,$A15,'Conciliación pipas'!$G$5:$G$40,"NO CUADRA")>0,"NO CUADRA",IF(COUNTIFS('Conciliación pipas'!$A$5:$A$40,$A15,'Conciliación pipas'!$G$5:$G$40,"CUADRA")>0,IF(COUNTIFS('Conciliación pipas'!$A$5:$A$40,$A15,'Conciliación pipas'!$G$5:$G$40,"SIN REPORTE")>0,"PARCIAL","CUADRA"),IF(COUNTIF('Conciliación pipas'!$A$5:$A$40,$A15)=0,"s/d","SIN REPORTE"))) -> NO CUADRA | I15: =SUMIFS('Conciliación pipas'!$H$5:$H$40,'Conciliación pipas'!$A$5:$A$40,$A15) -> 1
A16: COMBULUB | B16: =IF(COUNTIFS('Mermas mensual'!$A$5:$A$22,$A16,'Mermas mensual'!$B$5:$B$22,"Regular")=0,"s/d",IF(SUMIFS('Mermas mensual'!$E$5:$E$22,'Mermas mensual'!$A$5:$A$22,$A16,'Mermas mensual'!$B$5:$B$22,"Regular")=0,0,SUMIFS('Mermas mensual'!$I$5:$I$22,'Mermas mensual'!$A$5:$A$22,$A16,'Mermas mensual'!$B$5:$B$22,"Regular")/SUMIFS('Mermas mensual'!$E$5:$E$22,'Mermas mensual'!$A$5:$A$22,$A16,'Mermas mensual'!$B$5:$B$22,"Regular"))) -> s/d | C16: =IF(COUNTIFS('Mermas mensual'!$A$5:$A$22,$A16,'Mermas mensual'!$B$5:$B$22,"Premium")=0,"s/d",IF(SUMIFS('Mermas mensual'!$E$5:$E$22,'Mermas mensual'!$A$5:$A$22,$A16,'Mermas mensual'!$B$5:$B$22,"Premium")=0,0,SUMIFS('Mermas mensual'!$I$5:$I$22,'Mermas mensual'!$A$5:$A$22,$A16,'Mermas mensual'!$B$5:$B$22,"Premium")/SUMIFS('Mermas mensual'!$E$5:$E$22,'Mermas mensual'!$A$5:$A$22,$A16,'Mermas mensual'!$B$5:$B$22,"Premium"))) -> s/d | D16: =IF(COUNTIFS('Mermas mensual'!$A$5:$A$22,$A16,'Mermas mensual'!$B$5:$B$22,"Diesel")=0,"s/d",IF(SUMIFS('Mermas mensual'!$E$5:$E$22,'Mermas mensual'!$A$5:$A$22,$A16,'Mermas mensual'!$B$5:$B$22,"Diesel")=0,0,SUMIFS('Mermas mensual'!$I$5:$I$22,'Mermas mensual'!$A$5:$A$22,$A16,'Mermas mensual'!$B$5:$B$22,"Diesel")/SUMIFS('Mermas mensual'!$E$5:$E$22,'Mermas mensual'!$A$5:$A$22,$A16,'Mermas mensual'!$B$5:$B$22,"Diesel"))) -> s/d | E16: =IF(COUNTIF('Mermas mensual'!$A$5:$A$22,$A16)=0,"s/d",IF(SUMIFS('Mermas mensual'!$E$5:$E$22,'Mermas mensual'!$A$5:$A$22,$A16)=0,0,SUMIFS('Mermas mensual'!$I$5:$I$22,'Mermas mensual'!$A$5:$A$22,$A16)/SUMIFS('Mermas mensual'!$E$5:$E$22,'Mermas mensual'!$A$5:$A$22,$A16))) -> s/d | F16: =IF(COUNTIF('Mermas mensual'!$A$5:$A$22,$A16)=0,"s/d",SUMIFS('Mermas mensual'!$I$5:$I$22,'Mermas mensual'!$A$5:$A$22,$A16)) -> s/d | G16: =IF(COUNTIF('Mermas mensual'!$A$5:$A$22,$A16)=0,"s/d",SUMIFS('Mermas mensual'!$M$5:$M$22,'Mermas mensual'!$A$5:$A$22,$A16)) -> s/d | H16: =IF(COUNTIFS('Conciliación pipas'!$A$5:$A$40,$A16,'Conciliación pipas'!$G$5:$G$40,"NO CUADRA")>0,"NO CUADRA",IF(COUNTIFS('Conciliación pipas'!$A$5:$A$40,$A16,'Conciliación pipas'!$G$5:$G$40,"CUADRA")>0,IF(COUNTIFS('Conciliación pipas'!$A$5:$A$40,$A16,'Conciliación pipas'!$G$5:$G$40,"SIN REPORTE")>0,"PARCIAL","CUADRA"),IF(COUNTIF('Conciliación pipas'!$A$5:$A$40,$A16)=0,"s/d","SIN REPORTE"))) -> SIN REPORTE | I16: =SUMIFS('Conciliación pipas'!$H$5:$H$40,'Conciliación pipas'!$A$5:$A$40,$A16) -> 0
A17: HUEHUETOCA | B17: =IF(COUNTIFS('Mermas mensual'!$A$5:$A$22,$A17,'Mermas mensual'!$B$5:$B$22,"Regular")=0,"s/d",IF(SUMIFS('Mermas mensual'!$E$5:$E$22,'Mermas mensual'!$A$5:$A$22,$A17,'Mermas mensual'!$B$5:$B$22,"Regular")=0,0,SUMIFS('Mermas mensual'!$I$5:$I$22,'Mermas mensual'!$A$5:$A$22,$A17,'Mermas mensual'!$B$5:$B$22,"Regular")/SUMIFS('Mermas mensual'!$E$5:$E$22,'Mermas mensual'!$A$5:$A$22,$A17,'Mermas mensual'!$B$5:$B$22,"Regular"))) -> -0.0054329434 | C17: =IF(COUNTIFS('Mermas mensual'!$A$5:$A$22,$A17,'Mermas mensual'!$B$5:$B$22,"Premium")=0,"s/d",IF(SUMIFS('Mermas mensual'!$E$5:$E$22,'Mermas mensual'!$A$5:$A$22,$A17,'Mermas mensual'!$B$5:$B$22,"Premium")=0,0,SUMIFS('Mermas mensual'!$I$5:$I$22,'Mermas mensual'!$A$5:$A$22,$A17,'Mermas mensual'!$B$5:$B$22,"Premium")/SUMIFS('Mermas mensual'!$E$5:$E$22,'Mermas mensual'!$A$5:$A$22,$A17,'Mermas mensual'!$B$5:$B$22,"Premium"))) -> -0.0029814637 | D17: =IF(COUNTIFS('Mermas mensual'!$A$5:$A$22,$A17,'Mermas mensual'!$B$5:$B$22,"Diesel")=0,"s/d",IF(SUMIFS('Mermas mensual'!$E$5:$E$22,'Mermas mensual'!$A$5:$A$22,$A17,'Mermas mensual'!$B$5:$B$22,"Diesel")=0,0,SUMIFS('Mermas mensual'!$I$5:$I$22,'Mermas mensual'!$A$5:$A$22,$A17,'Mermas mensual'!$B$5:$B$22,"Diesel")/SUMIFS('Mermas mensual'!$E$5:$E$22,'Mermas mensual'!$A$5:$A$22,$A17,'Mermas mensual'!$B$5:$B$22,"Diesel"))) -> -0.0042455339 | E17: =IF(COUNTIF('Mermas mensual'!$A$5:$A$22,$A17)=0,"s/d",IF(SUMIFS('Mermas mensual'!$E$5:$E$22,'Mermas mensual'!$A$5:$A$22,$A17)=0,0,SUMIFS('Mermas mensual'!$I$5:$I$22,'Mermas mensual'!$A$5:$A$22,$A17)/SUMIFS('Mermas mensual'!$E$5:$E$22,'Mermas mensual'!$A$5:$A$22,$A17))) -> -0.0048737038 | F17: =IF(COUNTIF('Mermas mensual'!$A$5:$A$22,$A17)=0,"s/d",SUMIFS('Mermas mensual'!$I$5:$I$22,'Mermas mensual'!$A$5:$A$22,$A17)) -> -3857.85 | G17: =IF(COUNTIF('Mermas mensual'!$A$5:$A$22,$A17)=0,"s/d",SUMIFS('Mermas mensual'!$M$5:$M$22,'Mermas mensual'!$A$5:$A$22,$A17)) -> -76454.13 | H17: =IF(COUNTIFS('Conciliación pipas'!$A$5:$A$40,$A17,'Conciliación pipas'!$G$5:$G$40,"NO CUADRA")>0,"NO CUADRA",IF(COUNTIFS('Conciliación pipas'!$A$5:$A$40,$A17,'Conciliación pipas'!$G$5:$G$40,"CUADRA")>0,IF(COUNTIFS('Conciliación pipas'!$A$5:$A$40,$A17,'Conciliación pipas'!$G$5:$G$40,"SIN REPORTE")>0,"PARCIAL","CUADRA"),IF(COUNTIF('Conciliación pipas'!$A$5:$A$40,$A17)=0,"s/d","SIN REPORTE"))) -> CUADRA | I17: =SUMIFS('Conciliación pipas'!$H$5:$H$40,'Conciliación pipas'!$A$5:$A$40,$A17) -> 0
A18: QL | B18: =IF(COUNTIFS('Mermas mensual'!$A$5:$A$22,$A18,'Mermas mensual'!$B$5:$B$22,"Regular")=0,"s/d",IF(SUMIFS('Mermas mensual'!$E$5:$E$22,'Mermas mensual'!$A$5:$A$22,$A18,'Mermas mensual'!$B$5:$B$22,"Regular")=0,0,SUMIFS('Mermas mensual'!$I$5:$I$22,'Mermas mensual'!$A$5:$A$22,$A18,'Mermas mensual'!$B$5:$B$22,"Regular")/SUMIFS('Mermas mensual'!$E$5:$E$22,'Mermas mensual'!$A$5:$A$22,$A18,'Mermas mensual'!$B$5:$B$22,"Regular"))) -> -0.0047053512 | C18: =IF(COUNTIFS('Mermas mensual'!$A$5:$A$22,$A18,'Mermas mensual'!$B$5:$B$22,"Premium")=0,"s/d",IF(SUMIFS('Mermas mensual'!$E$5:$E$22,'Mermas mensual'!$A$5:$A$22,$A18,'Mermas mensual'!$B$5:$B$22,"Premium")=0,0,SUMIFS('Mermas mensual'!$I$5:$I$22,'Mermas mensual'!$A$5:$A$22,$A18,'Mermas mensual'!$B$5:$B$22,"Premium")/SUMIFS('Mermas mensual'!$E$5:$E$22,'Mermas mensual'!$A$5:$A$22,$A18,'Mermas mensual'!$B$5:$B$22,"Premium"))) -> -0.0064908831 | D18: =IF(COUNTIFS('Mermas mensual'!$A$5:$A$22,$A18,'Mermas mensual'!$B$5:$B$22,"Diesel")=0,"s/d",IF(SUMIFS('Mermas mensual'!$E$5:$E$22,'Mermas mensual'!$A$5:$A$22,$A18,'Mermas mensual'!$B$5:$B$22,"Diesel")=0,0,SUMIFS('Mermas mensual'!$I$5:$I$22,'Mermas mensual'!$A$5:$A$22,$A18,'Mermas mensual'!$B$5:$B$22,"Diesel")/SUMIFS('Mermas mensual'!$E$5:$E$22,'Mermas mensual'!$A$5:$A$22,$A18,'Mermas mensual'!$B$5:$B$22,"Diesel"))) -> 0.0063870109 | E18: =IF(COUNTIF('Mermas mensual'!$A$5:$A$22,$A18)=0,"s/d",IF(SUMIFS('Mermas mensual'!$E$5:$E$22,'Mermas mensual'!$A$5:$A$22,$A18)=0,0,SUMIFS('Mermas mensual'!$I$5:$I$22,'Mermas mensual'!$A$5:$A$22,$A18)/SUMIFS('Mermas mensual'!$E$5:$E$22,'Mermas mensual'!$A$5:$A$22,$A18))) -> 0.00052847199 | F18: =IF(COUNTIF('Mermas mensual'!$A$5:$A$22,$A18)=0,"s/d",SUMIFS('Mermas mensual'!$I$5:$I$22,'Mermas mensual'!$A$5:$A$22,$A18)) -> 978.88 | G18: =IF(COUNTIF('Mermas mensual'!$A$5:$A$22,$A18)=0,"s/d",SUMIFS('Mermas mensual'!$M$5:$M$22,'Mermas mensual'!$A$5:$A$22,$A18)) -> 28014.586 | H18: =IF(COUNTIFS('Conciliación pipas'!$A$5:$A$40,$A18,'Conciliación pipas'!$G$5:$G$40,"NO CUADRA")>0,"NO CUADRA",IF(COUNTIFS('Conciliación pipas'!$A$5:$A$40,$A18,'Conciliación pipas'!$G$5:$G$40,"CUADRA")>0,IF(COUNTIFS('Conciliación pipas'!$A$5:$A$40,$A18,'Conciliación pipas'!$G$5:$G$40,"SIN REPORTE")>0,"PARCIAL","CUADRA"),IF(COUNTIF('Conciliación pipas'!$A$5:$A$40,$A18)=0,"s/d","SIN REPORTE"))) -> CUADRA | I18: =SUMIFS('Conciliación pipas'!$H$5:$H$40,'Conciliación pipas'!$A$5:$A$40,$A18) -> 0
A19: IXTAZACUALA | B19: =IF(COUNTIFS('Mermas mensual'!$A$5:$A$22,$A19,'Mermas mensual'!$B$5:$B$22,"Regular")=0,"s/d",IF(SUMIFS('Mermas mensual'!$E$5:$E$22,'Mermas mensual'!$A$5:$A$22,$A19,'Mermas mensual'!$B$5:$B$22,"Regular")=0,0,SUMIFS('Mermas mensual'!$I$5:$I$22,'Mermas mensual'!$A$5:$A$22,$A19,'Mermas mensual'!$B$5:$B$22,"Regular")/SUMIFS('Mermas mensual'!$E$5:$E$22,'Mermas mensual'!$A$5:$A$22,$A19,'Mermas mensual'!$B$5:$B$22,"Regular"))) -> -0.0055998104 | C19: =IF(COUNTIFS('Mermas mensual'!$A$5:$A$22,$A19,'Mermas mensual'!$B$5:$B$22,"Premium")=0,"s/d",IF(SUMIFS('Mermas mensual'!$E$5:$E$22,'Mermas mensual'!$A$5:$A$22,$A19,'Mermas mensual'!$B$5:$B$22,"Premium")=0,0,SUMIFS('Mermas mensual'!$I$5:$I$22,'Mermas mensual'!$A$5:$A$22,$A19,'Mermas mensual'!$B$5:$B$22,"Premium")/SUMIFS('Mermas mensual'!$E$5:$E$22,'Mermas mensual'!$A$5:$A$22,$A19,'Mermas mensual'!$B$5:$B$22,"Premium"))) -> -0.0094117742 | D19: =IF(COUNTIFS('Mermas mensual'!$A$5:$A$22,$A19,'Mermas mensual'!$B$5:$B$22,"Diesel")=0,"s/d",IF(SUMIFS('Mermas mensual'!$E$5:$E$22,'Mermas mensual'!$A$5:$A$22,$A19,'Mermas mensual'!$B$5:$B$22,"Diesel")=0,0,SUMIFS('Mermas mensual'!$I$5:$I$22,'Mermas mensual'!$A$5:$A$22,$A19,'Mermas mensual'!$B$5:$B$22,"Diesel")/SUMIFS('Mermas mensual'!$E$5:$E$22,'Mermas mensual'!$A$5:$A$22,$A19,'Mermas mensual'!$B$5:$B$22,"Diesel"))) -> 0.00018556007 | E19: =IF(COUNTIF('Mermas mensual'!$A$5:$A$22,$A19)=0,"s/d",IF(SUMIFS('Mermas mensual'!$E$5:$E$22,'Mermas mensual'!$A$5:$A$22,$A19)=0,0,SUMIFS('Mermas mensual'!$I$5:$I$22,'Mermas mensual'!$A$5:$A$22,$A19)/SUMIFS('Mermas mensual'!$E$5:$E$22,'Mermas mensual'!$A$5:$A$22,$A19))) -> -0.0033777986 | F19: =IF(COUNTIF('Mermas mensual'!$A$5:$A$22,$A19)=0,"s/d",SUMIFS('Mermas mensual'!$I$5:$I$22,'Mermas mensual'!$A$5:$A$22,$A19)) -> -2427.34 | G19: =IF(COUNTIF('Mermas mensual'!$A$5:$A$22,$A19)=0,"s/d",SUMIFS('Mermas mensual'!$M$5:$M$22,'Mermas mensual'!$A$5:$A$22,$A19)) -> -48130.659 | H19: =IF(COUNTIFS('Conciliación pipas'!$A$5:$A$40,$A19,'Conciliación pipas'!$G$5:$G$40,"NO CUADRA")>0,"NO CUADRA",IF(COUNTIFS('Conciliación pipas'!$A$5:$A$40,$A19,'Conciliación pipas'!$G$5:$G$40,"CUADRA")>0,IF(COUNTIFS('Conciliación pipas'!$A$5:$A$40,$A19,'Conciliación pipas'!$G$5:$G$40,"SIN REPORTE")>0,"PARCIAL","CUADRA"),IF(COUNTIF('Conciliación pipas'!$A$5:$A$40,$A19)=0,"s/d","SIN REPORTE"))) -> CUADRA | I19: =SUMIFS('Conciliación pipas'!$H$5:$H$40,'Conciliación pipas'!$A$5:$A$40,$A19) -> 0
A20: TREHER | B20: =IF(COUNTIFS('Mermas mensual'!$A$5:$A$22,$A20,'Mermas mensual'!$B$5:$B$22,"Regular")=0,"s/d",IF(SUMIFS('Mermas mensual'!$E$5:$E$22,'Mermas mensual'!$A$5:$A$22,$A20,'Mermas mensual'!$B$5:$B$22,"Regular")=0,0,SUMIFS('Mermas mensual'!$I$5:$I$22,'Mermas mensual'!$A$5:$A$22,$A20,'Mermas mensual'!$B$5:$B$22,"Regular")/SUMIFS('Mermas mensual'!$E$5:$E$22,'Mermas mensual'!$A$5:$A$22,$A20,'Mermas mensual'!$B$5:$B$22,"Regular"))) -> -0.0060210826 | C20: =IF(COUNTIFS('Mermas mensual'!$A$5:$A$22,$A20,'Mermas mensual'!$B$5:$B$22,"Premium")=0,"s/d",IF(SUMIFS('Mermas mensual'!$E$5:$E$22,'Mermas mensual'!$A$5:$A$22,$A20,'Mermas mensual'!$B$5:$B$22,"Premium")=0,0,SUMIFS('Mermas mensual'!$I$5:$I$22,'Mermas mensual'!$A$5:$A$22,$A20,'Mermas mensual'!$B$5:$B$22,"Premium")/SUMIFS('Mermas mensual'!$E$5:$E$22,'Mermas mensual'!$A$5:$A$22,$A20,'Mermas mensual'!$B$5:$B$22,"Premium"))) -> -0.0099483027 | D20: =IF(COUNTIFS('Mermas mensual'!$A$5:$A$22,$A20,'Mermas mensual'!$B$5:$B$22,"Diesel")=0,"s/d",IF(SUMIFS('Mermas mensual'!$E$5:$E$22,'Mermas mensual'!$A$5:$A$22,$A20,'Mermas mensual'!$B$5:$B$22,"Diesel")=0,0,SUMIFS('Mermas mensual'!$I$5:$I$22,'Mermas mensual'!$A$5:$A$22,$A20,'Mermas mensual'!$B$5:$B$22,"Diesel")/SUMIFS('Mermas mensual'!$E$5:$E$22,'Mermas mensual'!$A$5:$A$22,$A20,'Mermas mensual'!$B$5:$B$22,"Diesel"))) -> -0.001668718 | E20: =IF(COUNTIF('Mermas mensual'!$A$5:$A$22,$A20)=0,"s/d",IF(SUMIFS('Mermas mensual'!$E$5:$E$22,'Mermas mensual'!$A$5:$A$22,$A20)=0,0,SUMIFS('Mermas mensual'!$I$5:$I$22,'Mermas mensual'!$A$5:$A$22,$A20)/SUMIFS('Mermas mensual'!$E$5:$E$22,'Mermas mensual'!$A$5:$A$22,$A20))) -> -0.0045186915 | F20: =IF(COUNTIF('Mermas mensual'!$A$5:$A$22,$A20)=0,"s/d",SUMIFS('Mermas mensual'!$I$5:$I$22,'Mermas mensual'!$A$5:$A$22,$A20)) -> -2919.12 | G20: =IF(COUNTIF('Mermas mensual'!$A$5:$A$22,$A20)=0,"s/d",SUMIFS('Mermas mensual'!$M$5:$M$22,'Mermas mensual'!$A$5:$A$22,$A20)) -> -58520.049 | H20: =IF(COUNTIFS('Conciliación pipas'!$A$5:$A$40,$A20,'Conciliación pipas'!$G$5:$G$40,"NO CUADRA")>0,"NO CUADRA",IF(COUNTIFS('Conciliación pipas'!$A$5:$A$40,$A20,'Conciliación pipas'!$G$5:$G$40,"CUADRA")>0,IF(COUNTIFS('Conciliación pipas'!$A$5:$A$40,$A20,'Conciliación pipas'!$G$5:$G$40,"SIN REPORTE")>0,"PARCIAL","CUADRA"),IF(COUNTIF('Conciliación pipas'!$A$5:$A$40,$A20)=0,"s/d","SIN REPORTE"))) -> CUADRA | I20: =SUMIFS('Conciliación pipas'!$H$5:$H$40,'Conciliación pipas'!$A$5:$A$40,$A20) -> 0
A21: TH | B21: =IF(COUNTIFS('Mermas mensual'!$A$5:$A$22,$A21,'Mermas mensual'!$B$5:$B$22,"Regular")=0,"s/d",IF(SUMIFS('Mermas mensual'!$E$5:$E$22,'Mermas mensual'!$A$5:$A$22,$A21,'Mermas mensual'!$B$5:$B$22,"Regular")=0,0,SUMIFS('Mermas mensual'!$I$5:$I$22,'Mermas mensual'!$A$5:$A$22,$A21,'Mermas mensual'!$B$5:$B$22,"Regular")/SUMIFS('Mermas mensual'!$E$5:$E$22,'Mermas mensual'!$A$5:$A$22,$A21,'Mermas mensual'!$B$5:$B$22,"Regular"))) -> s/d | C21: =IF(COUNTIFS('Mermas mensual'!$A$5:$A$22,$A21,'Mermas mensual'!$B$5:$B$22,"Premium")=0,"s/d",IF(SUMIFS('Mermas mensual'!$E$5:$E$22,'Mermas mensual'!$A$5:$A$22,$A21,'Mermas mensual'!$B$5:$B$22,"Premium")=0,0,SUMIFS('Mermas mensual'!$I$5:$I$22,'Mermas mensual'!$A$5:$A$22,$A21,'Mermas mensual'!$B$5:$B$22,"Premium")/SUMIFS('Mermas mensual'!$E$5:$E$22,'Mermas mensual'!$A$5:$A$22,$A21,'Mermas mensual'!$B$5:$B$22,"Premium"))) -> s/d | D21: =IF(COUNTIFS('Mermas mensual'!$A$5:$A$22,$A21,'Mermas mensual'!$B$5:$B$22,"Diesel")=0,"s/d",IF(SUMIFS('Mermas mensual'!$E$5:$E$22,'Mermas mensual'!$A$5:$A$22,$A21,'Mermas mensual'!$B$5:$B$22,"Diesel")=0,0,SUMIFS('Mermas mensual'!$I$5:$I$22,'Mermas mensual'!$A$5:$A$22,$A21,'Mermas mensual'!$B$5:$B$22,"Diesel")/SUMIFS('Mermas mensual'!$E$5:$E$22,'Mermas mensual'!$A$5:$A$22,$A21,'Mermas mensual'!$B$5:$B$22,"Diesel"))) -> s/d | E21: =IF(COUNTIF('Mermas mensual'!$A$5:$A$22,$A21)=0,"s/d",IF(SUMIFS('Mermas mensual'!$E$5:$E$22,'Mermas mensual'!$A$5:$A$22,$A21)=0,0,SUMIFS('Mermas mensual'!$I$5:$I$22,'Mermas mensual'!$A$5:$A$22,$A21)/SUMIFS('Mermas mensual'!$E$5:$E$22,'Mermas mensual'!$A$5:$A$22,$A21))) -> s/d | F21: =IF(COUNTIF('Mermas mensual'!$A$5:$A$22,$A21)=0,"s/d",SUMIFS('Mermas mensual'!$I$5:$I$22,'Mermas mensual'!$A$5:$A$22,$A21)) -> s/d | G21: =IF(COUNTIF('Mermas mensual'!$A$5:$A$22,$A21)=0,"s/d",SUMIFS('Mermas mensual'!$M$5:$M$22,'Mermas mensual'!$A$5:$A$22,$A21)) -> s/d | H21: =IF(COUNTIFS('Conciliación pipas'!$A$5:$A$40,$A21,'Conciliación pipas'!$G$5:$G$40,"NO CUADRA")>0,"NO CUADRA",IF(COUNTIFS('Conciliación pipas'!$A$5:$A$40,$A21,'Conciliación pipas'!$G$5:$G$40,"CUADRA")>0,IF(COUNTIFS('Conciliación pipas'!$A$5:$A$40,$A21,'Conciliación pipas'!$G$5:$G$40,"SIN REPORTE")>0,"PARCIAL","CUADRA"),IF(COUNTIF('Conciliación pipas'!$A$5:$A$40,$A21)=0,"s/d","SIN REPORTE"))) -> SIN REPORTE | I21: =SUMIFS('Conciliación pipas'!$H$5:$H$40,'Conciliación pipas'!$A$5:$A$40,$A21) -> 0
A22: TOREMEX | B22: =IF(COUNTIFS('Mermas mensual'!$A$5:$A$22,$A22,'Mermas mensual'!$B$5:$B$22,"Regular")=0,"s/d",IF(SUMIFS('Mermas mensual'!$E$5:$E$22,'Mermas mensual'!$A$5:$A$22,$A22,'Mermas mensual'!$B$5:$B$22,"Regular")=0,0,SUMIFS('Mermas mensual'!$I$5:$I$22,'Mermas mensual'!$A$5:$A$22,$A22,'Mermas mensual'!$B$5:$B$22,"Regular")/SUMIFS('Mermas mensual'!$E$5:$E$22,'Mermas mensual'!$A$5:$A$22,$A22,'Mermas mensual'!$B$5:$B$22,"Regular"))) -> s/d | C22: =IF(COUNTIFS('Mermas mensual'!$A$5:$A$22,$A22,'Mermas mensual'!$B$5:$B$22,"Premium")=0,"s/d",IF(SUMIFS('Mermas mensual'!$E$5:$E$22,'Mermas mensual'!$A$5:$A$22,$A22,'Mermas mensual'!$B$5:$B$22,"Premium")=0,0,SUMIFS('Mermas mensual'!$I$5:$I$22,'Mermas mensual'!$A$5:$A$22,$A22,'Mermas mensual'!$B$5:$B$22,"Premium")/SUMIFS('Mermas mensual'!$E$5:$E$22,'Mermas mensual'!$A$5:$A$22,$A22,'Mermas mensual'!$B$5:$B$22,"Premium"))) -> s/d | D22: =IF(COUNTIFS('Mermas mensual'!$A$5:$A$22,$A22,'Mermas mensual'!$B$5:$B$22,"Diesel")=0,"s/d",IF(SUMIFS('Mermas mensual'!$E$5:$E$22,'Mermas mensual'!$A$5:$A$22,$A22,'Mermas mensual'!$B$5:$B$22,"Diesel")=0,0,SUMIFS('Mermas mensual'!$I$5:$I$22,'Mermas mensual'!$A$5:$A$22,$A22,'Mermas mensual'!$B$5:$B$22,"Diesel")/SUMIFS('Mermas mensual'!$E$5:$E$22,'Mermas mensual'!$A$5:$A$22,$A22,'Mermas mensual'!$B$5:$B$22,"Diesel"))) -> s/d | E22: =IF(COUNTIF('Mermas mensual'!$A$5:$A$22,$A22)=0,"s/d",IF(SUMIFS('Mermas mensual'!$E$5:$E$22,'Mermas mensual'!$A$5:$A$22,$A22)=0,0,SUMIFS('Mermas mensual'!$I$5:$I$22,'Mermas mensual'!$A$5:$A$22,$A22)/SUMIFS('Mermas mensual'!$E$5:$E$22,'Mermas mensual'!$A$5:$A$22,$A22))) -> s/d | F22: =IF(COUNTIF('Mermas mensual'!$A$5:$A$22,$A22)=0,"s/d",SUMIFS('Mermas mensual'!$I$5:$I$22,'Mermas mensual'!$A$5:$A$22,$A22)) -> s/d | G22: =IF(COUNTIF('Mermas mensual'!$A$5:$A$22,$A22)=0,"s/d",SUMIFS('Mermas mensual'!$M$5:$M$22,'Mermas mensual'!$A$5:$A$22,$A22)) -> s/d | H22: =IF(COUNTIFS('Conciliación pipas'!$A$5:$A$40,$A22,'Conciliación pipas'!$G$5:$G$40,"NO CUADRA")>0,"NO CUADRA",IF(COUNTIFS('Conciliación pipas'!$A$5:$A$40,$A22,'Conciliación pipas'!$G$5:$G$40,"CUADRA")>0,IF(COUNTIFS('Conciliación pipas'!$A$5:$A$40,$A22,'Conciliación pipas'!$G$5:$G$40,"SIN REPORTE")>0,"PARCIAL","CUADRA"),IF(COUNTIF('Conciliación pipas'!$A$5:$A$40,$A22)=0,"s/d","SIN REPORTE"))) -> SIN REPORTE | I22: =SUMIFS('Conciliación pipas'!$H$5:$H$40,'Conciliación pipas'!$A$5:$A$40,$A22) -> 0
A23: TEOLOYUCAN | B23: =IF(COUNTIFS('Mermas mensual'!$A$5:$A$22,$A23,'Mermas mensual'!$B$5:$B$22,"Regular")=0,"s/d",IF(SUMIFS('Mermas mensual'!$E$5:$E$22,'Mermas mensual'!$A$5:$A$22,$A23,'Mermas mensual'!$B$5:$B$22,"Regular")=0,0,SUMIFS('Mermas mensual'!$I$5:$I$22,'Mermas mensual'!$A$5:$A$22,$A23,'Mermas mensual'!$B$5:$B$22,"Regular")/SUMIFS('Mermas mensual'!$E$5:$E$22,'Mermas mensual'!$A$5:$A$22,$A23,'Mermas mensual'!$B$5:$B$22,"Regular"))) -> 0.020096157 | C23: =IF(COUNTIFS('Mermas mensual'!$A$5:$A$22,$A23,'Mermas mensual'!$B$5:$B$22,"Premium")=0,"s/d",IF(SUMIFS('Mermas mensual'!$E$5:$E$22,'Mermas mensual'!$A$5:$A$22,$A23,'Mermas mensual'!$B$5:$B$22,"Premium")=0,0,SUMIFS('Mermas mensual'!$I$5:$I$22,'Mermas mensual'!$A$5:$A$22,$A23,'Mermas mensual'!$B$5:$B$22,"Premium")/SUMIFS('Mermas mensual'!$E$5:$E$22,'Mermas mensual'!$A$5:$A$22,$A23,'Mermas mensual'!$B$5:$B$22,"Premium"))) -> 0.035197495 | D23: =IF(COUNTIFS('Mermas mensual'!$A$5:$A$22,$A23,'Mermas mensual'!$B$5:$B$22,"Diesel")=0,"s/d",IF(SUMIFS('Mermas mensual'!$E$5:$E$22,'Mermas mensual'!$A$5:$A$22,$A23,'Mermas mensual'!$B$5:$B$22,"Diesel")=0,0,SUMIFS('Mermas mensual'!$I$5:$I$22,'Mermas mensual'!$A$5:$A$22,$A23,'Mermas mensual'!$B$5:$B$22,"Diesel")/SUMIFS('Mermas mensual'!$E$5:$E$22,'Mermas mensual'!$A$5:$A$22,$A23,'Mermas mensual'!$B$5:$B$22,"Diesel"))) -> 0.0051166726 | E23: =IF(COUNTIF('Mermas mensual'!$A$5:$A$22,$A23)=0,"s/d",IF(SUMIFS('Mermas mensual'!$E$5:$E$22,'Mermas mensual'!$A$5:$A$22,$A23)=0,0,SUMIFS('Mermas mensual'!$I$5:$I$22,'Mermas mensual'!$A$5:$A$22,$A23)/SUMIFS('Mermas mensual'!$E$5:$E$22,'Mermas mensual'!$A$5:$A$22,$A23))) -> 0.014430254 | F23: =IF(COUNTIF('Mermas mensual'!$A$5:$A$22,$A23)=0,"s/d",SUMIFS('Mermas mensual'!$I$5:$I$22,'Mermas mensual'!$A$5:$A$22,$A23)) -> 5362.1 | G23: =IF(COUNTIF('Mermas mensual'!$A$5:$A$22,$A23)=0,"s/d",SUMIFS('Mermas mensual'!$M$5:$M$22,'Mermas mensual'!$A$5:$A$22,$A23)) -> 110873.89 | H23: =IF(COUNTIFS('Conciliación pipas'!$A$5:$A$40,$A23,'Conciliación pipas'!$G$5:$G$40,"NO CUADRA")>0,"NO CUADRA",IF(COUNTIFS('Conciliación pipas'!$A$5:$A$40,$A23,'Conciliación pipas'!$G$5:$G$40,"CUADRA")>0,IF(COUNTIFS('Conciliación pipas'!$A$5:$A$40,$A23,'Conciliación pipas'!$G$5:$G$40,"SIN REPORTE")>0,"PARCIAL","CUADRA"),IF(COUNTIF('Conciliación pipas'!$A$5:$A$40,$A23)=0,"s/d","SIN REPORTE"))) -> CUADRA | I23: =SUMIFS('Conciliación pipas'!$H$5:$H$40,'Conciliación pipas'!$A$5:$A$40,$A23) -> 0
A25: Semáforo: | B25: Verde: |merma| ≤ 0.40 % | D25: Amarillo: 0.40 % – 0.50 % | F25: Rojo: > 0.50 % (fuera SAT) | H25: s/d: sin reporte de mermas
A26: Negativo = faltante de combustible · Positivo = sobrante. Los umbrales se cambian en la hoja Parámetros.

Sheet Mermas mensual
A1: Mermas mensuales por estación y producto
A2: Periodo: Agosto 2026 · Generado: 22/09/2026 17:01 · Límite SAT: merma ≤ 0.5% de la venta
A4: Estación | B4: Producto | C4: Sdo. Inicial (1er día) | D4: Compras | E4: Ventas | F4: Ajustes | G4: Sdo. Final (teórico) | H4: Sdo. Real (último día) | I4: Merma (L) | J4: Merma % | K4: Estado | L4: Costo prom. pipas ($/L) | M4: Merma ($) | N4: Pipas NO registradas (L) | O4: Merma ajustada (L) | P4: Merma % ajustada | R4: Etiqueta gráfica
A5: AURORA | B5: Regular | C5: 39387.69 | D5: =SUMIFS('Detalle diario'!$E$5:$E$550,'Detalle diario'!$A$5:$A$550,A5,'Detalle diario'!$B$5:$B$550,B5)+SUMIFS('Detalle diario'!$L$5:$L$550,'Detalle diario'!$A$5:$A$550,A5,'Detalle diario'!$B$5:$B$550,B5) -> 643188 | E5: =SUMIFS('Detalle diario'!$F$5:$F$550,'Detalle diario'!$A$5:$A$550,A5,'Detalle diario'!$B$5:$B$550,B5) -> 649583.42 | F5: =SUMIFS('Detalle diario'!$G$5:$G$550,'Detalle diario'!$A$5:$A$550,A5,'Detalle diario'!$B$5:$B$550,B5) -> 0 | G5: =C5+D5-E5+F5 -> 32992.27 | H5: 62089.03 | I5: =H5-G5 -> 29096.76 | J5: =IF(E5=0,0,I5/E5) -> 0.044792954 | K5: =IF(ABS(J5)>Parámetros!$C$5,"FUERA",IF(ABS(J5)>Parámetros!$C$6,"ALERTA","OK")) -> FUERA | L5: 18.979 | M5: =I5*L5 -> 552227.41 | N5: =SUMIFS('Detalle pipas'!$G$5:$G$281,'Detalle pipas'!$A$5:$A$281,A5,'Detalle pipas'!$B$5:$B$281,B5,'Detalle pipas'!$L$5:$L$281,"NO REGISTRADA*") -> 33465 | O5: =I5-N5 -> -4368.24 | P5: =IF(E5=0,0,O5/E5) -> -0.006724679 | R5: =A5&" · "&B5 -> AURORA · Regular
A6: AURORA | B6: Premium | C6: 13598.9 | D6: =SUMIFS('Detalle diario'!$E$5:$E$550,'Detalle diario'!$A$5:$A$550,A6,'Detalle diario'!$B$5:$B$550,B6)+SUMIFS('Detalle diario'!$L$5:$L$550,'Detalle diario'!$A$5:$A$550,A6,'Detalle diario'!$B$5:$B$550,B6) -> 72049 | E6: =SUMIFS('Detalle diario'!$F$5:$F$550,'Detalle diario'!$A$5:$A$550,A6,'Detalle diario'!$B$5:$B$550,B6) -> 61367.16 | F6: =SUMIFS('Detalle diario'!$G$5:$G$550,'Detalle diario'!$A$5:$A$550,A6,'Detalle diario'!$B$5:$B$550,B6) -> 0 | G6: =C6+D6-E6+F6 -> 24280.74 | H6: 23878.08 | I6: =H6-G6 -> -402.66 | J6: =IF(E6=0,0,I6/E6) -> -0.0065614899 | K6: =IF(ABS(J6)>Parámetros!$C$5,"FUERA",IF(ABS(J6)>Parámetros!$C$6,"ALERTA","OK")) -> FUERA | L6: 22.3794 | M6: =I6*L6 -> -9011.2892 | N6: =SUMIFS('Detalle pipas'!$G$5:$G$281,'Detalle pipas'!$A$5:$A$281,A6,'Detalle pipas'!$B$5:$B$281,B6,'Detalle pipas'!$L$5:$L$281,"NO REGISTRADA*") -> 0 | O6: =I6-N6 -> -402.66 | P6: =IF(E6=0,0,O6/E6) -> -0.0065614899 | R6: =A6&" · "&B6 -> AURORA · Premium
A7: AURORA | B7: Diesel | C7: 27221.33 | D7: =SUMIFS('Detalle diario'!$E$5:$E$550,'Detalle diario'!$A$5:$A$550,A7,'Detalle diario'!$B$5:$B$550,B7)+SUMIFS('Detalle diario'!$L$5:$L$550,'Detalle diario'!$A$5:$A$550,A7,'Detalle diario'!$B$5:$B$550,B7) -> 287001 | E7: =SUMIFS('Detalle diario'!$F$5:$F$550,'Detalle diario'!$A$5:$A$550,A7,'Detalle diario'!$B$5:$B$550,B7) -> 286219.08 | F7: =SUMIFS('Detalle diario'!$G$5:$G$550,'Detalle diario'!$A$5:$A$550,A7,'Detalle diario'!$B$5:$B$550,B7) -> 0 | G7: =C7+D7-E7+F7 -> 28003.25 | H7: 28496.59 | I7: =H7-G7 -> 493.34 | J7: =IF(E7=0,0,I7/E7) -> 0.0017236447 | K7: =IF(ABS(J7)>Parámetros!$C$5,"FUERA",IF(ABS(J7)>Parámetros!$C$6,"ALERTA","OK")) -> OK | L7: 21.782 | M7: =I7*L7 -> 10745.932 | N7: =SUMIFS('Detalle pipas'!$G$5:$G$281,'Detalle pipas'!$A$5:$A$281,A7,'Detalle pipas'!$B$5:$B$281,B7,'Detalle pipas'!$L$5:$L$281,"NO REGISTRADA*") -> 0 | O7: =I7-N7 -> 493.34 | P7: =IF(E7=0,0,O7/E7) -> 0.0017236447 | R7: =A7&" · "&B7 -> AURORA · Diesel
A8: HUEHUETOCA | B8: Regular | C8: 24744.8 | D8: =SUMIFS('Detalle diario'!$E$5:$E$550,'Detalle diario'!$A$5:$A$550,A8,'Detalle diario'!$B$5:$B$550,B8)+SUMIFS('Detalle diario'!$L$5:$L$550,'Detalle diario'!$A$5:$A$550,A8,'Detalle diario'!$B$5:$B$550,B8) -> 512270 | E8: =SUMIFS('Detalle diario'!$F$5:$F$550,'Detalle diario'!$A$5:$A$550,A8,'Detalle diario'!$B$5:$B$550,B8) -> 474394.78 | F8: =SUMIFS('Detalle diario'!$G$5:$G$550,'Detalle diario'!$A$5:$A$550,A8,'Detalle diario'!$B$5:$B$550,B8) -> 0 | G8: =C8+D8-E8+F8 -> 62620.02 | H8: 60042.66 | I8: =H8-G8 -> -2577.36 | J8: =IF(E8=0,0,I8/E8) -> -0.0054329434 | K8: =IF(ABS(J8)>Parámetros!$C$5,"FUERA",IF(ABS(J8)>Parámetros!$C$6,"ALERTA","OK")) -> FUERA | L8: 18.8382 | M8: =I8*L8 -> -48552.823 | N8: =SUMIFS('Detalle pipas'!$G$5:$G$281,'Detalle pipas'!$A$5:$A$281,A8,'Detalle pipas'!$B$5:$B$281,B8,'Detalle pipas'!$L$5:$L$281,"NO REGISTRADA*") -> 0 | O8: =I8-N8 -> -2577.36 | P8: =IF(E8=0,0,O8/E8) -> -0.0054329434 | R8: =A8&" · "&B8 -> HUEHUETOCA · Regular
A9: HUEHUETOCA | B9: Premium | C9: 26497.19 | D9: =SUMIFS('Detalle diario'!$E$5:$E$550,'Detalle diario'!$A$5:$A$550,A9,'Detalle diario'!$B$5:$B$550,B9)+SUMIFS('Detalle diario'!$L$5:$L$550,'Detalle diario'!$A$5:$A$550,A9,'Detalle diario'!$B$5:$B$550,B9) -> 60101 | E9: =SUMIFS('Detalle diario'!$F$5:$F$550,'Detalle diario'!$A$5:$A$550,A9,'Detalle diario'!$B$5:$B$550,B9) -> 52262.92 | F9: =SUMIFS('Detalle diario'!$G$5:$G$550,'Detalle diario'!$A$5:$A$550,A9,'Detalle diario'!$B$5:$B$550,B9) -> 0 | G9: =C9+D9-E9+F9 -> 34335.27 | H9: 34179.45 | I9: =H9-G9 -> -155.82 | J9: =IF(E9=0,0,I9/E9) -> -0.0029814637 | K9: =IF(ABS(J9)>Parámetros!$C$5,"FUERA",IF(ABS(J9)>Parámetros!$C$6,"ALERTA","OK")) -> OK | L9: 22.4114 | M9: =I9*L9 -> -3492.1443 | N9: =SUMIFS('Detalle pipas'!$G$5:$G$281,'Detalle pipas'!$A$5:$A$281,A9,'Detalle pipas'!$B$5:$B$281,B9,'Detalle pipas'!$L$5:$L$281,"NO REGISTRADA*") -> 0 | O9: =I9-N9 -> -155.82 | P9: =IF(E9=0,0,O9/E9) -> -0.0029814637 | R9: =A9&" · "&B9 -> HUEHUETOCA · Premium
A10: HUEHUETOCA | B10: Diesel | C10: 46175.06 | D10: =SUMIFS('Detalle diario'!$E$5:$E$550,'Detalle diario'!$A$5:$A$550,A10,'Detalle diario'!$B$5:$B$550,B10)+SUMIFS('Detalle diario'!$L$5:$L$550,'Detalle diario'!$A$5:$A$550,A10,'Detalle diario'!$B$5:$B$550,B10) -> 272939 | E10: =SUMIFS('Detalle diario'!$F$5:$F$550,'Detalle diario'!$A$5:$A$550,A10,'Detalle diario'!$B$5:$B$550,B10) -> 264906.61 | F10: =SUMIFS('Detalle diario'!$G$5:$G$550,'Detalle diario'!$A$5:$A$550,A10,'Detalle diario'!$B$5:$B$550,B10) -> 0 | G10: =C10+D10-E10+F10 -> 54207.45 | H10: 53082.78 | I10: =H10-G10 -> -1124.67 | J10: =IF(E10=0,0,I10/E10) -> -0.0042455339 | K10: =IF(ABS(J10)>Parámetros!$C$5,"FUERA",IF(ABS(J10)>Parámetros!$C$6,"ALERTA","OK")) -> ALERTA | L10: 21.7034 | M10: =I10*L10 -> -24409.163 | N10: =SUMIFS('Detalle pipas'!$G$5:$G$281,'Detalle pipas'!$A$5:$A$281,A10,'Detalle pipas'!$B$5:$B$281,B10,'Detalle pipas'!$L$5:$L$281,"NO REGISTRADA*") -> 0 | O10: =I10-N10 -> -1124.67 | P10: =IF(E10=0,0,O10/E10) -> -0.0042455339 | R10: =A10&" · "&B10 -> HUEHUETOCA · Diesel
A11: QL | B11: Regular | C11: 164102.01 | D11: =SUMIFS('Detalle diario'!$E$5:$E$550,'Detalle diario'!$A$5:$A$550,A11,'Detalle diario'!$B$5:$B$550,B11)+SUMIFS('Detalle diario'!$L$5:$L$550,'Detalle diario'!$A$5:$A$550,A11,'Detalle diario'!$B$5:$B$550,B11) -> 579699 | E11: =SUMIFS('Detalle diario'!$F$5:$F$550,'Detalle diario'!$A$5:$A$550,A11,'Detalle diario'!$B$5:$B$550,B11) -> 611397.51 | F11: =SUMIFS('Detalle diario'!$G$5:$G$550,'Detalle diario'!$A$5:$A$550,A11,'Detalle diario'!$B$5:$B$550,B11) -> 0 | G11: =C11+D11-E11+F11 -> 132403.5 | H11: 129526.66 | I11: =H11-G11 -> -2876.84 | J11: =IF(E11=0,0,I11/E11) -> -0.0047053512 | K11: =IF(ABS(J11)>Parámetros!$C$5,"FUERA",IF(ABS(J11)>Parámetros!$C$6,"ALERTA","OK")) -> ALERTA | L11: 18.9784 | M11: =I11*L11 -> -54597.82 | N11: =SUMIFS('Detalle pipas'!$G$5:$G$281,'Detalle pipas'!$A$5:$A$281,A11,'Detalle pipas'!$B$5:$B$281,B11,'Detalle pipas'!$L$5:$L$281,"NO REGISTRADA*") -> 0 | O11: =I11-N11 -> -2876.84 | P11: =IF(E11=0,0,O11/E11) -> -0.0047053512 | R11: =A11&" · "&B11 -> QL · Regular
A12: QL | B12: Premium | C12: 62944.93 | D12: =SUMIFS('Detalle diario'!$E$5:$E$550,'Detalle diario'!$A$5:$A$550,A12,'Detalle diario'!$B$5:$B$550,B12)+SUMIFS('Detalle diario'!$L$5:$L$550,'Detalle diario'!$A$5:$A$550,A12,'Detalle diario'!$B$5:$B$550,B12) -> 300298 | E12: =SUMIFS('Detalle diario'!$F$5:$F$550,'Detalle diario'!$A$5:$A$550,A12,'Detalle diario'!$B$5:$B$550,B12) -> 316032.5 | F12: =SUMIFS('Detalle diario'!$G$5:$G$550,'Detalle diario'!$A$5:$A$550,A12,'Detalle diario'!$B$5:$B$550,B12) -> 0 | G12: =C12+D12-E12+F12 -> 47210.43 | H12: 45159.1 | I12: =H12-G12 -> -2051.33 | J12: =IF(E12=0,0,I12/E12) -> -0.0064908831 | K12: =IF(ABS(J12)>Parámetros!$C$5,"FUERA",IF(ABS(J12)>Parámetros!$C$6,"ALERTA","OK")) -> FUERA | L12: 22.5031 | M12: =I12*L12 -> -46161.284 | N12: =SUMIFS('Detalle pipas'!$G$5:$G$281,'Detalle pipas'!$A$5:$A$281,A12,'Detalle pipas'!$B$5:$B$281,B12,'Detalle pipas'!$L$5:$L$281,"NO REGISTRADA*") -> 0 | O12: =I12-N12 -> -2051.33 | P12: =IF(E12=0,0,O12/E12) -> -0.0064908831 | R12: =A12&" · "&B12 -> QL · Premium
A13: QL | B13: Diesel | C13: 117500.54 | D13: =SUMIFS('Detalle diario'!$E$5:$E$550,'Detalle diario'!$A$5:$A$550,A13,'Detalle diario'!$B$5:$B$550,B13)+SUMIFS('Detalle diario'!$L$5:$L$550,'Detalle diario'!$A$5:$A$550,A13,'Detalle diario'!$B$5:$B$550,B13) -> 877365 | E13: =SUMIFS('Detalle diario'!$F$5:$F$550,'Detalle diario'!$A$5:$A$550,A13,'Detalle diario'!$B$5:$B$550,B13) -> 924853.59 | F13: =SUMIFS('Detalle diario'!$G$5:$G$550,'Detalle diario'!$A$5:$A$550,A13,'Detalle diario'!$B$5:$B$550,B13) -> 0 | G13: =C13+D13-E13+F13 -> 70011.95 | H13: 75919 | I13: =H13-G13 -> 5907.05 | J13: =IF(E13=0,0,I13/E13) -> 0.0063870109 | K13: =IF(ABS(J13)>Parámetros!$C$5,"FUERA",IF(ABS(J13)>Parámetros!$C$6,"ALERTA","OK")) -> FUERA | L13: 21.8 | M13: =I13*L13 -> 128773.69 | N13: =SUMIFS('Detalle pipas'!$G$5:$G$281,'Detalle pipas'!$A$5:$A$281,A13,'Detalle pipas'!$B$5:$B$281,B13,'Detalle pipas'!$L$5:$L$281,"NO REGISTRADA*") -> 0 | O13: =I13-N13 -> 5907.05 | P13: =IF(E13=0,0,O13/E13) -> 0.0063870109 | R13: =A13&" · "&B13 -> QL · Diesel
A14: IXTAZACUALA | B14: Regular | C14: 0 | D14: =SUMIFS('Detalle diario'!$E$5:$E$550,'Detalle diario'!$A$5:$A$550,A14,'Detalle diario'!$B$5:$B$550,B14)+SUMIFS('Detalle diario'!$L$5:$L$550,'Detalle diario'!$A$5:$A$550,A14,'Detalle diario'!$B$5:$B$550,B14) -> 332823 | E14: =SUMIFS('Detalle diario'!$F$5:$F$550,'Detalle diario'!$A$5:$A$550,A14,'Detalle diario'!$B$5:$B$550,B14) -> 347704.63 | F14: =SUMIFS('Detalle diario'!$G$5:$G$550,'Detalle diario'!$A$5:$A$550,A14,'Detalle diario'!$B$5:$B$550,B14) -> 51578 | G14: =C14+D14-E14+F14 -> 36696.37 | H14: 34749.29 | I14: =H14-G14 -> -1947.08 | J14: =IF(E14=0,0,I14/E14) -> -0.0055998104 | K14: =IF(ABS(J14)>Parámetros!$C$5,"FUERA",IF(ABS(J14)>Parámetros!$C$6,"ALERTA","OK")) -> FUERA | L14: 19.128 | M14: =I14*L14 -> -37243.746 | N14: =SUMIFS('Detalle pipas'!$G$5:$G$281,'Detalle pipas'!$A$5:$A$281,A14,'Detalle pipas'!$B$5:$B$281,B14,'Detalle pipas'!$L$5:$L$281,"NO REGISTRADA*") -> 0 | O14: =I14-N14 -> -1947.08 | P14: =IF(E14=0,0,O14/E14) -> -0.0055998104 | R14: =A14&" · "&B14 -> IXTAZACUALA · Regular
A15: IXTAZACUALA | B15: Premium | C15: 0 | D15: =SUMIFS('Detalle diario'!$E$5:$E$550,'Detalle diario'!$A$5:$A$550,A15,'Detalle diario'!$B$5:$B$550,B15)+SUMIFS('Detalle diario'!$L$5:$L$550,'Detalle diario'!$A$5:$A$550,A15,'Detalle diario'!$B$5:$B$550,B15) -> 59834 | E15: =SUMIFS('Detalle diario'!$F$5:$F$550,'Detalle diario'!$A$5:$A$550,A15,'Detalle diario'!$B$5:$B$550,B15) -> 57212.38 | F15: =SUMIFS('Detalle diario'!$G$5:$G$550,'Detalle diario'!$A$5:$A$550,A15,'Detalle diario'!$B$5:$B$550,B15) -> 27932 | G15: =C15+D15-E15+F15 -> 30553.62 | H15: 30015.15 | I15: =H15-G15 -> -538.47 | J15: =IF(E15=0,0,I15/E15) -> -0.0094117742 | K15: =IF(ABS(J15)>Parámetros!$C$5,"FUERA",IF(ABS(J15)>Parámetros!$C$6,"ALERTA","OK")) -> FUERA | L15: 22.5882 | M15: =I15*L15 -> -12163.068 | N15: =SUMIFS('Detalle pipas'!$G$5:$G$281,'Detalle pipas'!$A$5:$A$281,A15,'Detalle pipas'!$B$5:$B$281,B15,'Detalle pipas'!$L$5:$L$281,"NO REGISTRADA*") -> 0 | O15: =I15-N15 -> -538.47 | P15: =IF(E15=0,0,O15/E15) -> -0.0094117742 | R15: =A15&" · "&B15 -> IXTAZACUALA · Premium
A16: IXTAZACUALA | B16: Diesel | C16: 0 | D16: =SUMIFS('Detalle diario'!$E$5:$E$550,'Detalle diario'!$A$5:$A$550,A16,'Detalle diario'!$B$5:$B$550,B16)+SUMIFS('Detalle diario'!$L$5:$L$550,'Detalle diario'!$A$5:$A$550,A16,'Detalle diario'!$B$5:$B$550,B16) -> 303295 | E16: =SUMIFS('Detalle diario'!$F$5:$F$550,'Detalle diario'!$A$5:$A$550,A16,'Detalle diario'!$B$5:$B$550,B16) -> 313698.96 | F16: =SUMIFS('Detalle diario'!$G$5:$G$550,'Detalle diario'!$A$5:$A$550,A16,'Detalle diario'!$B$5:$B$550,B16) -> 38703 | G16: =C16+D16-E16+F16 -> 28299.04 | H16: 28357.25 | I16: =H16-G16 -> 58.21 | J16: =IF(E16=0,0,I16/E16) -> 0.00018556007 | K16: =IF(ABS(J16)>Parámetros!$C$5,"FUERA",IF(ABS(J16)>Parámetros!$C$6,"ALERTA","OK")) -> OK | L16: 21.9233 | M16: =I16*L16 -> 1276.1553 | N16: =SUMIFS('Detalle pipas'!$G$5:$G$281,'Detalle pipas'!$A$5:$A$281,A16,'Detalle pipas'!$B$5:$B$281,B16,'Detalle pipas'!$L$5:$L$281,"NO REGISTRADA*") -> 0 | O16: =I16-N16 -> 58.21 | P16: =IF(E16=0,0,O16/E16) -> 0.00018556007 | R16: =A16&" · "&B16 -> IXTAZACUALA · Diesel
... A22: TEOLOYUCAN | B22: Diesel | C22: 60935.26 | D22: =SUMIFS('Detalle diario'!$E$5:$E$550,'Detalle diario'!$A$5:$A$550,A22,'Detalle diario'!$B$5:$B$550,B22)+SUMIFS('Detalle diario'!$L$5:$L$550,'Detalle diario'!$A$5:$A$550,A22,'Detalle diario'!$B$5:$B$550,B22) -> 166412 | E22: =SUMIFS('Detalle diario'!$F$5:$F$550,'Detalle diario'!$A$5:$A$550,A22,'Detalle diario'!$B$5:$B$550,B22) -> 194806.29 | F22: =SUMIFS('Detalle diario'!$G$5:$G$550,'Detalle diario'!$A$5:$A$550,A22,'Detalle diario'!$B$5:$B$550,B22) -> 0 | G22: =C22+D22-E22+F22 -> 32540.97 | H22: 33537.73 | I22: =H22-G22 -> 996.76 | J22: =IF(E22=0,0,I22/E22) -> 0.0051166726 | K22: =IF(ABS(J22)>Parámetros!$C$5,"FUERA",IF(ABS(J22)>Parámetros!$C$6,"ALERTA","OK")) -> FUERA | L22: 21.8312 | M22: =I22*L22 -> 21760.467 | N22: =SUMIFS('Detalle pipas'!$G$5:$G$281,'Detalle pipas'!$A$5:$A$281,A22,'Detalle pipas'!$B$5:$B$281,B22,'Detalle pipas'!$L$5:$L$281,"NO REGISTRADA*") -> 0 | O22: =I22-N22 -> 996.76 | P22: =IF(E22=0,0,O22/E22) -> 0.0051166726 | R22: =A22&" · "&B22 -> TEOLOYUCAN · Diesel
A23: TOTAL GRUPO | C23: =SUM(C5:C22) -> 800950.46 | D23: =SUM(D5:D22) -> 5246240 | E23: =SUM(E5:E22) -> 5377230.9 | F23: =SUM(F5:F22) -> 118213 | G23: =SUM(G5:G22) -> 788172.54 | H23: =SUM(H5:H22) -> 814496.65 | I23: =SUM(I5:I22) -> 26324.11 | J23: =IF(E23=0,0,I23/E23) -> 0.0048954769 | K23: =IF(ABS(J23)>Parámetros!$C$5,"FUERA",IF(ABS(J23)>Parámetros!$C$6,"ALERTA","OK")) -> ALERTA | M23: =SUM(M5:M22) -> 509745.69 | N23: =SUM(N5:N22) -> 33465 | O23: =SUM(O5:O22) -> -7140.89 | P23: =IF(E23=0,0,O23/E23) -> -0.0013279865
A25: Merma = Sdo. Real − Sdo. Final; Sdo. Final = Sdo. Inicial + Compras − Ventas + Ajustes; Merma % = Merma / Ventas. Negativo = faltante, positivo = sobrante.
A26: Costo prom. = promedio ponderado del CTO UNIT de las pipas del mes (dato del Excel de pipas); Merma ($) = Merma (L) × Costo prom.
A27: Merma ajustada = Merma − litros de pipas NO registradas: si una pipa llegó físicamente pero no se capturó, aparece como sobrante. Es un indicador de apoyo; el oficial es Merma %.
A28: Compras incluye lo capturado en la hoja Registros manuales.

Sheet Compras sin pipa
A1: Compras registradas en mermas que no se encontraron en PIPAS DEL MES
A2: Periodo: Agosto 2026 · Generado: 22/09/2026 17:01 · Límite SAT: merma ≤ 0.5% de la venta
A4: Estación | B4: Producto | C4: Fecha | D4: Litros | E4: Nota
A5: ✔ Todas las compras del reporte de mermas tienen una pipa que las respalda.

Sheet Detalle diario
A1: Detalle diario de mermas
A2: Periodo: Agosto 2026 · Generado: 22/09/2026 17:01 · Límite SAT: merma ≤ 0.5% de la venta
A4: Estación | B4: Producto | C4: Fecha | D4: Sdo. Inicial | E4: Compras | F4: Ventas | G4: Ajustes | H4: Sdo. Final | I4: Sdo. Real | J4: Merma | K4: Merma % | L4: Compras manuales
A5: AURORA | B5: Regular | C5: 46235 | D5: 39387.69 | E5: 36301 | F5: 21890.23 | G5: 0 | H5: =D5+E5+L5-F5+G5 -> 53798.46 | I5: 53530.23 | J5: =I5-H5 -> -268.23 | K5: =IF(F5=0,0,J5/F5) -> -0.012253412 | L5: =SUMIFS('Registros manuales'!$D$5:$D$104,'Registros manuales'!$A$5:$A$104,A5,'Registros manuales'!$B$5:$B$104,B5,'Registros manuales'!$C$5:$C$104,C5) -> 0
A6: AURORA | B6: Regular | C6: 46236 | D6: 53530.23 | E6: 0 | F6: 21607.51 | G6: 0 | H6: =D6+E6+L6-F6+G6 -> 31922.72 | I6: 31700.8 | J6: =I6-H6 -> -221.92 | K6: =IF(F6=0,0,J6/F6) -> -0.010270503 | L6: =SUMIFS('Registros manuales'!$D$5:$D$104,'Registros manuales'!$A$5:$A$104,A6,'Registros manuales'!$B$5:$B$104,B6,'Registros manuales'!$C$5:$C$104,C6) -> 0
A7: AURORA | B7: Regular | C7: 46237 | D7: 31700.8 | E7: 0 | F7: 21480.42 | G7: 0 | H7: =D7+E7+L7-F7+G7 -> 10220.38 | I7: 46203.5 | J7: =I7-H7 -> 35983.12 | K7: =IF(F7=0,0,J7/F7) -> 1.6751591 | L7: =SUMIFS('Registros manuales'!$D$5:$D$104,'Registros manuales'!$A$5:$A$104,A7,'Registros manuales'!$B$5:$B$104,B7,'Registros manuales'!$C$5:$C$104,C7) -> 0
A8: AURORA | B8: Regular | C8: 46238 | D8: 46203.5 | E8: 71939 | F8: 19654.4 | G8: 0 | H8: =D8+E8+L8-F8+G8 -> 98488.1 | I8: 62940.98 | J8: =I8-H8 -> -35547.12 | K8: =IF(F8=0,0,J8/F8) -> -1.8086088 | L8: =SUMIFS('Registros manuales'!$D$5:$D$104,'Registros manuales'!$A$5:$A$104,A8,'Registros manuales'!$B$5:$B$104,B8,'Registros manuales'!$C$5:$C$104,C8) -> 0
A9: AURORA | B9: Regular | C9: 46239 | D9: 62940.98 | E9: 36205 | F9: 18995.34 | G9: 0 | H9: =D9+E9+L9-F9+G9 -> 80150.64 | I9: 80328.18 | J9: =I9-H9 -> 177.54 | K9: =IF(F9=0,0,J9/F9) -> 0.0093465029 | L9: =SUMIFS('Registros manuales'!$D$5:$D$104,'Registros manuales'!$A$5:$A$104,A9,'Registros manuales'!$B$5:$B$104,B9,'Registros manuales'!$C$5:$C$104,C9) -> 0
A10: AURORA | B10: Regular | C10: 46240 | D10: 80328.18 | E10: 0 | F10: 18973.63 | G10: 0 | H10: =D10+E10+L10-F10+G10 -> 61354.55 | I10: 60852.39 | J10: =I10-H10 -> -502.16 | K10: =IF(F10=0,0,J10/F10) -> -0.026466206 | L10: =SUMIFS('Registros manuales'!$D$5:$D$104,'Registros manuales'!$A$5:$A$104,A10,'Registros manuales'!$B$5:$B$104,B10,'Registros manuales'!$C$5:$C$104,C10) -> 0
A11: AURORA | B11: Regular | C11: 46241 | D11: 60852.39 | E11: 0 | F11: 20761.1 | G11: 0 | H11: =D11+E11+L11-F11+G11 -> 40091.29 | I11: 76261.01 | J11: =I11-H11 -> 36169.72 | K11: =IF(F11=0,0,J11/F11) -> 1.7421871 | L11: =SUMIFS('Registros manuales'!$D$5:$D$104,'Registros manuales'!$A$5:$A$104,A11,'Registros manuales'!$B$5:$B$104,B11,'Registros manuales'!$C$5:$C$104,C11) -> 0
A12: AURORA | B12: Regular | C12: 46242 | D12: 76261.01 | E12: 0 | F12: 22083.9 | G12: 0 | H12: =D12+E12+L12-F12+G12 -> 54177.11 | I12: 53582.48 | J12: =I12-H12 -> -594.63 | K12: =IF(F12=0,0,J12/F12) -> -0.026925951 | L12: =SUMIFS('Registros manuales'!$D$5:$D$104,'Registros manuales'!$A$5:$A$104,A12,'Registros manuales'!$B$5:$B$104,B12,'Registros manuales'!$C$5:$C$104,C12) -> 0
A13: AURORA | B13: Regular | C13: 46243 | D13: 53582.48 | E13: 35932 | F13: 20327.96 | G13: 0 | H13: =D13+E13+L13-F13+G13 -> 69186.52 | I13: 32968.45 | J13: =I13-H13 -> -36218.07 | K13: =IF(F13=0,0,J13/F13) -> -1.7816874 | L13: =SUMIFS('Registros manuales'!$D$5:$D$104,'Registros manuales'!$A$5:$A$104,A13,'Registros manuales'!$B$5:$B$104,B13,'Registros manuales'!$C$5:$C$104,C13) -> 0
A14: AURORA | B14: Regular | C14: 46244 | D14: 32968.45 | E14: 0 | F14: 19657.01 | G14: 0 | H14: =D14+E14+L14-F14+G14 -> 13311.44 | I14: 49495.2 | J14: =I14-H14 -> 36183.76 | K14: =IF(F14=0,0,J14/F14) -> 1.840756 | L14: =SUMIFS('Registros manuales'!$D$5:$D$104,'Registros manuales'!$A$5:$A$104,A14,'Registros manuales'!$B$5:$B$104,B14,'Registros manuales'!$C$5:$C$104,C14) -> 0
A15: AURORA | B15: Regular | C15: 46245 | D15: 49495.2 | E15: 72420 | F15: 19919.71 | G15: 0 | H15: =D15+E15+L15-F15+G15 -> 101995.49 | I15: 65871.94 | J15: =I15-H15 -> -36123.55 | K15: =IF(F15=0,0,J15/F15) -> -1.8134576 | L15: =SUMIFS('Registros manuales'!$D$5:$D$104,'Registros manuales'!$A$5:$A$104,A15,'Registros manuales'!$B$5:$B$104,B15,'Registros manuales'!$C$5:$C$104,C15) -> 0
A16: AURORA | B16: Regular | C16: 46246 | D16: 65871.94 | E16: 36007 | F16: 19356.4 | G16: 0 | H16: =D16+E16+L16-F16+G16 -> 82522.54 | I16: 82826.43 | J16: =I16-H16 -> 303.89 | K16: =IF(F16=0,0,J16/F16) -> 0.015699717 | L16: =SUMIFS('Registros manuales'!$D$5:$D$104,'Registros manuales'!$A$5:$A$104,A16,'Registros manuales'!$B$5:$B$104,B16,'Registros manuales'!$C$5:$C$104,C16) -> 0
... A550: TEOLOYUCAN | B550: Diesel | C550: 46265 | D550: 38280.1 | E550: 0 | F550: 4727.86 | G550: 0 | H550: =D550+E550+L550-F550+G550 -> 33552.24 | I550: 33537.73 | J550: =I550-H550 -> -14.51 | K550: =IF(F550=0,0,J550/F550) -> -0.0030690418 | L550: =SUMIFS('Registros manuales'!$D$5:$D$104,'Registros manuales'!$A$5:$A$104,A550,'Registros manuales'!$B$5:$B$104,B550,'Registros manuales'!$C$5:$C$104,C550) -> 0

Sheet Conciliación pipas
A1: Conciliación de compras: Reporte de mermas vs PIPAS DEL MES
A2: Periodo: Agosto 2026 · Generado: 22/09/2026 17:01 · Límite SAT: merma ≤ 0.5% de la venta
A4: Estación | B4: Producto | C4: Compras reporte mermas (L) | D4: Litros PIPAS DEL MES | E4: # Pipas | F4: Diferencia (L) mermas − pipas | G4: Estado | H4: Pipas no registradas | I4: Pipas con desfase | J4: Compras sin pipa | K4: Comentario
A5: ATB | B5: Regular | C5: Sin reporte | D5: =SUMIFS('Detalle pipas'!$G$5:$G$281,'Detalle pipas'!$A$5:$A$281,A5,'Detalle pipas'!$B$5:$B$281,B5,'Detalle pipas'!$M$5:$M$281,"Sí") -> 87211 | E5: =COUNTIFS('Detalle pipas'!$A$5:$A$281,A5,'Detalle pipas'!$B$5:$B$281,B5,'Detalle pipas'!$M$5:$M$281,"Sí") -> 3 | F5: =IF(ISNUMBER(C5),C5-D5,"") | G5: =IF(NOT(ISNUMBER(C5)),"SIN REPORTE",IF(ABS(F5)<=Parámetros!$C$8*MAX(1,E5),"CUADRA","NO CUADRA")) -> SIN REPORTE | H5: =COUNTIFS('Detalle pipas'!$A$5:$A$281,A5,'Detalle pipas'!$B$5:$B$281,B5,'Detalle pipas'!$L$5:$L$281,"NO REGISTRADA*") -> 0 | I5: =COUNTIFS('Detalle pipas'!$A$5:$A$281,A5,'Detalle pipas'!$B$5:$B$281,B5,'Detalle pipas'!$L$5:$L$281,"Registrada con desfase*") -> 0 | J5: =COUNTIFS('Compras sin pipa'!$A$5:$A$5,A5,'Compras sin pipa'!$B$5:$B$5,B5)+COUNTIFS('Registros manuales'!$A$5:$A$104,A5,'Registros manuales'!$B$5:$B$104,B5,'Registros manuales'!$G$5:$G$104,"SIN PIPA*") -> 0 | K5: =IF(COUNTIFS('Detalle pipas'!$A$5:$A$281,A5,'Detalle pipas'!$B$5:$B$281,B5,'Detalle pipas'!$L$5:$L$281,"REGISTRO MANUAL*")>0,"Incluye "&COUNTIFS('Detalle pipas'!$A$5:$A$281,A5,'Detalle pipas'!$B$5:$B$281,B5,'Detalle pipas'!$L$5:$L$281,"REGISTRO MANUAL*")&" registro(s) manual(es) · ","")&IF(G5="SIN REPORTE","Falta el CSV de mermas de esta estación/producto",IF(G5="CUADRA",IF(I5>0,"Cuadra en el mes; hay pipas registradas en otro día (ver Detalle pipas)","Todo en orden"),"Revisar: "&H5&" pipa(s) sin registrar y "&J5&" compra(s) sin pipa"))&IF(COUNTIFS('Detalle pipas'!$A$5:$A$281,A5,'Detalle pipas'!$B$5:$B$281,B5,'Detalle pipas'!$M$5:$M$281,"No")>0," · "&COUNTIFS('Detalle pipas'!$A$5:$A$281,A5,'Detalle pipas'!$B$5:$B$281,B5,'Detalle pipas'!$M$5:$M$281,"No")&" pipa(s) antes del inicio del reporte (no se cuentan)","") -> Falta el CSV de mermas de esta estación/producto
A6: ATB | B6: Premium | C6: Sin reporte | D6: =SUMIFS('Detalle pipas'!$G$5:$G$281,'Detalle pipas'!$A$5:$A$281,A6,'Detalle pipas'!$B$5:$B$281,B6,'Detalle pipas'!$M$5:$M$281,"Sí") -> 10198 | E6: =COUNTIFS('Detalle pipas'!$A$5:$A$281,A6,'Detalle pipas'!$B$5:$B$281,B6,'Detalle pipas'!$M$5:$M$281,"Sí") -> 1 | F6: =IF(ISNUMBER(C6),C6-D6,"") | G6: =IF(NOT(ISNUMBER(C6)),"SIN REPORTE",IF(ABS(F6)<=Parámetros!$C$8*MAX(1,E6),"CUADRA","NO CUADRA")) -> SIN REPORTE | H6: =COUNTIFS('Detalle pipas'!$A$5:$A$281,A6,'Detalle pipas'!$B$5:$B$281,B6,'Detalle pipas'!$L$5:$L$281,"NO REGISTRADA*") -> 0 | I6: =COUNTIFS('Detalle pipas'!$A$5:$A$281,A6,'Detalle pipas'!$B$5:$B$281,B6,'Detalle pipas'!$L$5:$L$281,"Registrada con desfase*") -> 0 | J6: =COUNTIFS('Compras sin pipa'!$A$5:$A$5,A6,'Compras sin pipa'!$B$5:$B$5,B6)+COUNTIFS('Registros manuales'!$A$5:$A$104,A6,'Registros manuales'!$B$5:$B$104,B6,'Registros manuales'!$G$5:$G$104,"SIN PIPA*") -> 0 | K6: =IF(COUNTIFS('Detalle pipas'!$A$5:$A$281,A6,'Detalle pipas'!$B$5:$B$281,B6,'Detalle pipas'!$L$5:$L$281,"REGISTRO MANUAL*")>0,"Incluye "&COUNTIFS('Detalle pipas'!$A$5:$A$281,A6,'Detalle pipas'!$B$5:$B$281,B6,'Detalle pipas'!$L$5:$L$281,"REGISTRO MANUAL*")&" registro(s) manual(es) · ","")&IF(G6="SIN REPORTE","Falta el CSV de mermas de esta estación/producto",IF(G6="CUADRA",IF(I6>0,"Cuadra en el mes; hay pipas registradas en otro día (ver Detalle pipas)","Todo en orden"),"Revisar: "&H6&" pipa(s) sin registrar y "&J6&" compra(s) sin pipa"))&IF(COUNTIFS('Detalle pipas'!$A$5:$A$281,A6,'Detalle pipas'!$B$5:$B$281,B6,'Detalle pipas'!$M$5:$M$281,"No")>0," · "&COUNTIFS('Detalle pipas'!$A$5:$A$281,A6,'Detalle pipas'!$B$5:$B$281,B6,'Detalle pipas'!$M$5:$M$281,"No")&" pipa(s) antes del inicio del reporte (no se cuentan)","") -> Falta el CSV de mermas de esta estación/producto
A7: ATB | B7: Diesel | C7: Sin reporte | D7: =SUMIFS('Detalle pipas'!$G$5:$G$281,'Detalle pipas'!$A$5:$A$281,A7,'Detalle pipas'!$B$5:$B$281,B7,'Detalle pipas'!$M$5:$M$281,"Sí") -> 66767 | E7: =COUNTIFS('Detalle pipas'!$A$5:$A$281,A7,'Detalle pipas'!$B$5:$B$281,B7,'Detalle pipas'!$M$5:$M$281,"Sí") -> 2 | F7: =IF(ISNUMBER(C7),C7-D7,"") | G7: =IF(NOT(ISNUMBER(C7)),"SIN REPORTE",IF(ABS(F7)<=Parámetros!$C$8*MAX(1,E7),"CUADRA","NO CUADRA")) -> SIN REPORTE | H7: =COUNTIFS('Detalle pipas'!$A$5:$A$281,A7,'Detalle pipas'!$B$5:$B$281,B7,'Detalle pipas'!$L$5:$L$281,"NO REGISTRADA*") -> 0 | I7: =COUNTIFS('Detalle pipas'!$A$5:$A$281,A7,'Detalle pipas'!$B$5:$B$281,B7,'Detalle pipas'!$L$5:$L$281,"Registrada con desfase*") -> 0 | J7: =COUNTIFS('Compras sin pipa'!$A$5:$A$5,A7,'Compras sin pipa'!$B$5:$B$5,B7)+COUNTIFS('Registros manuales'!$A$5:$A$104,A7,'Registros manuales'!$B$5:$B$104,B7,'Registros manuales'!$G$5:$G$104,"SIN PIPA*") -> 0 | K7: =IF(COUNTIFS('Detalle pipas'!$A$5:$A$281,A7,'Detalle pipas'!$B$5:$B$281,B7,'Detalle pipas'!$L$5:$L$281,"REGISTRO MANUAL*")>0,"Incluye "&COUNTIFS('Detalle pipas'!$A$5:$A$281,A7,'Detalle pipas'!$B$5:$B$281,B7,'Detalle pipas'!$L$5:$L$281,"REGISTRO MANUAL*")&" registro(s) manual(es) · ","")&IF(G7="SIN REPORTE","Falta el CSV de mermas de esta estación/producto",IF(G7="CUADRA",IF(I7>0,"Cuadra en el mes; hay pipas registradas en otro día (ver Detalle pipas)","Todo en orden"),"Revisar: "&H7&" pipa(s) sin registrar y "&J7&" compra(s) sin pipa"))&IF(COUNTIFS('Detalle pipas'!$A$5:$A$281,A7,'Detalle pipas'!$B$5:$B$281,B7,'Detalle pipas'!$M$5:$M$281,"No")>0," · "&COUNTIFS('Detalle pipas'!$A$5:$A$281,A7,'Detalle pipas'!$B$5:$B$281,B7,'Detalle pipas'!$M$5:$M$281,"No")&" pipa(s) antes del inicio del reporte (no se cuentan)","") -> Falta el CSV de mermas de esta estación/producto
A8: ATP | B8: Regular | C8: Sin reporte | D8: =SUMIFS('Detalle pipas'!$G$5:$G$281,'Detalle pipas'!$A$5:$A$281,A8,'Detalle pipas'!$B$5:$B$281,B8,'Detalle pipas'!$M$5:$M$281,"Sí") -> 147203 | E8: =COUNTIFS('Detalle pipas'!$A$5:$A$281,A8,'Detalle pipas'!$B$5:$B$281,B8,'Detalle pipas'!$M$5:$M$281,"Sí") -> 5 | F8: =IF(ISNUMBER(C8),C8-D8,"") | G8: =IF(NOT(ISNUMBER(C8)),"SIN REPORTE",IF(ABS(F8)<=Parámetros!$C$8*MAX(1,E8),"CUADRA","NO CUADRA")) -> SIN REPORTE | H8: =COUNTIFS('Detalle pipas'!$A$5:$A$281,A8,'Detalle pipas'!$B$5:$B$281,B8,'Detalle pipas'!$L$5:$L$281,"NO REGISTRADA*") -> 0 | I8: =COUNTIFS('Detalle pipas'!$A$5:$A$281,A8,'Detalle pipas'!$B$5:$B$281,B8,'Detalle pipas'!$L$5:$L$281,"Registrada con desfase*") -> 0 | J8: =COUNTIFS('Compras sin pipa'!$A$5:$A$5,A8,'Compras sin pipa'!$B$5:$B$5,B8)+COUNTIFS('Registros manuales'!$A$5:$A$104,A8,'Registros manuales'!$B$5:$B$104,B8,'Registros manuales'!$G$5:$G$104,"SIN PIPA*") -> 0 | K8: =IF(COUNTIFS('Detalle pipas'!$A$5:$A$281,A8,'Detalle pipas'!$B$5:$B$281,B8,'Detalle pipas'!$L$5:$L$281,"REGISTRO MANUAL*")>0,"Incluye "&COUNTIFS('Detalle pipas'!$A$5:$A$281,A8,'Detalle pipas'!$B$5:$B$281,B8,'Detalle pipas'!$L$5:$L$281,"REGISTRO MANUAL*")&" registro(s) manual(es) · ","")&IF(G8="SIN REPORTE","Falta el CSV de mermas de esta estación/producto",IF(G8="CUADRA",IF(I8>0,"Cuadra en el mes; hay pipas registradas en otro día (ver Detalle pipas)","Todo en orden"),"Revisar: "&H8&" pipa(s) sin registrar y "&J8&" compra(s) sin pipa"))&IF(COUNTIFS('Detalle pipas'!$A$5:$A$281,A8,'Detalle pipas'!$B$5:$B$281,B8,'Detalle pipas'!$M$5:$M$281,"No")>0," · "&COUNTIFS('Detalle pipas'!$A$5:$A$281,A8,'Detalle pipas'!$B$5:$B$281,B8,'Detalle pipas'!$M$5:$M$281,"No")&" pipa(s) antes del inicio del reporte (no se cuentan)","") -> Falta el CSV de mermas de esta estación/producto
A9: ATP | B9: Premium | C9: Sin reporte | D9: =SUMIFS('Detalle pipas'!$G$5:$G$281,'Detalle pipas'!$A$5:$A$281,A9,'Detalle pipas'!$B$5:$B$281,B9,'Detalle pipas'!$M$5:$M$281,"Sí") -> 10139 | E9: =COUNTIFS('Detalle pipas'!$A$5:$A$281,A9,'Detalle pipas'!$B$5:$B$281,B9,'Detalle pipas'!$M$5:$M$281,"Sí") -> 1 | F9: =IF(ISNUMBER(C9),C9-D9,"") | G9: =IF(NOT(ISNUMBER(C9)),"SIN REPORTE",IF(ABS(F9)<=Parámetros!$C$8*MAX(1,E9),"CUADRA","NO CUADRA")) -> SIN REPORTE | H9: =COUNTIFS('Detalle pipas'!$A$5:$A$281,A9,'Detalle pipas'!$B$5:$B$281,B9,'Detalle pipas'!$L$5:$L$281,"NO REGISTRADA*") -> 0 | I9: =COUNTIFS('Detalle pipas'!$A$5:$A$281,A9,'Detalle pipas'!$B$5:$B$281,B9,'Detalle pipas'!$L$5:$L$281,"Registrada con desfase*") -> 0 | J9: =COUNTIFS('Compras sin pipa'!$A$5:$A$5,A9,'Compras sin pipa'!$B$5:$B$5,B9)+COUNTIFS('Registros manuales'!$A$5:$A$104,A9,'Registros manuales'!$B$5:$B$104,B9,'Registros manuales'!$G$5:$G$104,"SIN PIPA*") -> 0 | K9: =IF(COUNTIFS('Detalle pipas'!$A$5:$A$281,A9,'Detalle pipas'!$B$5:$B$281,B9,'Detalle pipas'!$L$5:$L$281,"REGISTRO MANUAL*")>0,"Incluye "&COUNTIFS('Detalle pipas'!$A$5:$A$281,A9,'Detalle pipas'!$B$5:$B$281,B9,'Detalle pipas'!$L$5:$L$281,"REGISTRO MANUAL*")&" registro(s) manual(es) · ","")&IF(G9="SIN REPORTE","Falta el CSV de mermas de esta estación/producto",IF(G9="CUADRA",IF(I9>0,"Cuadra en el mes; hay pipas registradas en otro día (ver Detalle pipas)","Todo en orden"),"Revisar: "&H9&" pipa(s) sin registrar y "&J9&" compra(s) sin pipa"))&IF(COUNTIFS('Detalle pipas'!$A$5:$A$281,A9,'Detalle pipas'!$B$5:$B$281,B9,'Detalle pipas'!$M$5:$M$281,"No")>0," · "&COUNTIFS('Detalle pipas'!$A$5:$A$281,A9,'Detalle pipas'!$B$5:$B$281,B9,'Detalle pipas'!$M$5:$M$281,"No")&" pipa(s) antes del inicio del reporte (no se cuentan)","") -> Falta el CSV de mermas de esta estación/producto
